{
    "query": "任务运行出现NaN，原因是什么？",
    "summaries": [
        "程序在运行过程中因代理连接失败导致异常退出。错误信息显示无法连接到代理，网络不可达，进而引发与 wandb 通信失败，最终导致程序异常终止。 traceback 显示错误发生在训练过程中的回调函数调用期间，具体是 wandb 初始化时出现问题。该问题可能影响模型训练的记录和跟踪功能。",
        "用户反映NCL画图速度过慢，经排查发现是数据数值过大导致。将数据除以10^27后问题解决，画图速度明显提升。建议在处理大数据时适当归一化，以提高绘图效率。",
        "HPC4及3K运行deepmd-gromacs时出现报错“Step 0: The total potential energy is -nan”，提示能量值非有限，可能由坐标值过大、初始结构未平衡或参数错误引起。解决方法为取消环境变量GMX_DEEPMD_INPUT_JSON的设置，以避免潜在冲突。"
    ],
    "contents": [
        "read=None, redirect=None, status=None)) after connection broken by 'ProxyError('Cannot connect to proxy.', NewConnectionError('<urllib3.connection.HTTPSConnection object at 0x1507b20a8d00>: Failed to establish a new connection: [Errno 101] Network is unreachable'))': /api/5288891/store/\nwandb: ERROR Abnormal program exit\nTraceback (most recent call last):\nFile \"/fs1/home/dush2/anaconda3/envs/lmflow5/lib/python3.9/site-packages/wandb/sdk/wandb_init.py\", line 1144, in init\nrun = wi.init()\nFile \"/fs1/home/dush2/anaconda3/envs/lmflow5/lib/python3.9/site-packages/wandb/sdk/wandb_init.py\", line 773, in init\nraise error\nwandb.errors.CommError: Error communicating with wandb process, exiting...\nFor more info see: https://docs.wandb.ai/guides/track/tracking-faq#initstarterror-error-communicating-with-wandb-process-\nThe above exception was the direct cause of the following exception:\nTraceback (most recent call last):\nFile \"/fs1/home/dush2/LMFlow/examples/finetune.py\", line 61, in <module>\nmain()\nFile \"/fs1/home/dush2/LMFlow/examples/finetune.py\", line 57, in main\ntuned_model = finetuner.tune(model=model, dataset=dataset)\nFile \"/fs1/home/dush2/LMFlow/src/lmflow/pipeline/finetuner.py\", line 274, in tune\ntrain_result = trainer.train(resume_from_checkpoint=checkpoint)\nFile \"/fs1/home/dush2/anaconda3/envs/lmflow5/lib/python3.9/site-packages/transformers/trainer.py\", line 1639, in train\nreturn inner",
        "【已解决】HPC4及3K运行deepmd-gromacs报Step 0: The total potential energy is -nan\n**标签**: 无标签\n**创建时间**: 2024-08-26 10:45:28\n**更新时间**: 2024-08-26 10:45:28\n**作者**: 杜思慧\n**1. 报错**\nFatal error\nMH, which is not finite. The LJ and\nelectrostatic contributions to the energy are @ and 0, respectively. A\nnon-finite potential energy can be caused by overlapping interactions in\nbonded interactions or very large or Nan coordinate values. Usually this is\ncaused by a badly- or non-equilibrated initial configuration, incorrect\ninteractions or parameters in the topology.\nFor more information and tips for troubleshooting, please check the GROMACS\nwebsite at http://www. gromacs.org/Documentat ion/Errors\nMPI_ABORT was invoked on rank 9 in communicator MPI_COMM WORLD\nwith errorcode 1.\nNOTE: invoking MPI_ABORT causes Open MPI to kill all MPI processes.\nYou may or may not see output from other processes, depending on\nexactly when Open MPI kills them.\nMPI_ABORT was invoked on rank 1 in communicator MPI_COMM WORLD\nwith errorcode 1.\nNOTE: invoking MPI_ABORT causes Open MPI to kill all MPI processes.\nYou may or may not see output from other processes, depending on\nexactly when Open MPI kills them.\nyhrun: Job step aborted: Waiting up to 32 seconds for job step to finish.\nslurmstepd: error: ***",
        "Open MPI kills them.\nyhrun: Job step aborted: Waiting up to 32 seconds for job step to finish.\nslurmstepd: error: *** STEP 1897628.0 ON cn1827 CANCELLED AT 2024-08-23T16:42:41 ***\nslurmstepd: error: *** STEP 1897628.0 ON cn1827 CANCELLED AT 2024-08-23T16:42:41 ***\nyhrun: error: cn1827: tasks 0-1: Exited with exit code 1\n**2.解决**\nunset GMX_DEEPMD_INPUT_JSON",
        "_checkpoint=checkpoint)\nFile \"/fs1/home/dush2/anaconda3/envs/lmflow5/lib/python3.9/site-packages/transformers/trainer.py\", line 1639, in train\nreturn inner_training_loop(\nFile \"/fs1/home/dush2/anaconda3/envs/lmflow5/lib/python3.9/site-packages/transformers/trainer.py\", line 1822, in _inner_training_loop\nself.control = self.callback_handler.on_train_begin(args, self.state, self.control)\nFile \"/fs1/home/dush2/anaconda3/envs/lmflow5/lib/python3.9/site-packages/transformers/trainer_callback.py\", line 353, in on_train_begin\nreturn self.call_event(\"on_train_begin\", args, state, control)\nFile \"/fs1/home/dush2/anaconda3/envs/lmflow5/lib/python3.9/site-packages/transformers/trainer_callback.py\", line 397, in call_event\nresult = getattr(callback, event)(\nFile \"/fs1/home/dush2/anaconda3/envs/lmflow5/lib/python3.9/site-packages/transformers/integrations.py\", line 764, in on_train_begin\nself.setup(args, state, model, **kwargs)\nFile \"/fs1/home/dush2/anaconda3/envs/lmflow5/lib/python3.9/site-packages/transformers/integrations.py\", line 738, in setup\nself._wandb.init(\nFile \"/fs1/home/dush2/anaconda3/envs/lmflow5/lib/python3.9/site-packages/wandb/sdk/wandb_init.py\", line 1181, in init\nraise Exception(\"problem\") from error_seen\nException: problem",
        "【已解决】NCL画图速度过慢\n**标签**: 无标签\n**创建时间**: 2024-08-05 10:54:30\n**更新时间**: 2024-08-05 10:54:30\n**作者**: 张天奇\n数据数值过大，数值除个10^27次方就能出来"
    ]
}